Error executing Python script:

TypeError: parent exception

Traceback (most recent call last):
  File "data_function.py", in _execute_script
    exec(compiled_script, self.globals)
    ~~~~^^^^^^^^^^^^^^^^^^^^^^^^^^^^^^^
  File "<data_function>", in <module>

The following exception was the direct cause of the above exception:

Traceback (most recent call last):
  File "<data_function>", in <module>
ValueError: root exception
